// Exception handling problem using the nested try catch block

class Code {

    public static void main(String... code) {

        while (true) {

            System.out.println("Enter the value of n: ");

            Scanner s = new Scanner(System.in);

            int n = s.nextInt();

            try {

                System.out.println("The output is : " + 10 / n);

            } catch (ArithmeticException e) {

                try {

                    System.out.println("Enter the index to find the character at the index: ");

                    int m =s.nextInt();

                            System.out.println("The character at the given index is: " + "abhishek".charAt(m));

                }

                catch (Exception r){

                    System.out.println("Ooopss, the exception occured is:"+ r);

                }

            }System.out.println("The task finished\n Thank You");

        }

    }

}

/*

Enter the value of n: 

0

Enter the index to find the character at the index: 

1

The character at the given index is: b

The task finished

 Thank You


 */
 
 
 
 // Problem: Usage of System.exit(0) in nested exception program. 

class Code {

    public static void main(String... code) {

        while (true) {

            System.out.println("Enter the value of n: ");

            Scanner s = new Scanner(System.in);

            int n = s.nextInt();

            try {

                System.out.println("The output is : " + 10 / n);

                System.exit(1);

            } catch (ArithmeticException e) {

                try {

                    System.out.println("Enter the index to find the character at the index: ");

                    int m =s.nextInt();

                    System.out.println("The character at the given index is: " + "abhishek".charAt(m));

                }

                catch (Exception r){

                    System.out.println("Ooopss, the exception occured is:"+ r);

                }

            }System.out.println("The task finished\n Thank You");

        }

    }

}

/*

Enter the value of n:

2

The output is : 5

 */



// Using finally block in the exception handling problem.

class Code{

 public static int divide(int a, int b) throws ArithmeticException{

  int res=a/b;

  return res;

 }

 public static int add(int c, int d){

  int f=c+d;

  return f;

 }

 public static void main(String... java){

  int f=add(2,3);

  System.out.println("The sum of c and d is: "+ f);

  try {

   int c = divide(4, 0);

   System.out.println(c);

  }

  catch (Exception e){

   System.out.println("Checked Exception... please try again");

  }

  finally {

   System.out.println("Code execution is finished");

  }

 }

}

/*

The sum of c and d is: 5

Checked Exception... please try again

Code execution is finished

 */
 
 
 // Using finally block in the exception handling problem.

class Code{

 public static int divide(int a, int b) throws ArithmeticException{

  int res=a/b;

  return res;

 }

 public static int add(int c, int d){

  int f=c+d;

  return f;

 }

 public static void main(String... java){

  try {

   int c = divide(4, 0);

   System.out.println(c);

  }

  catch (Exception e){

   System.out.println("Checked Exception... please try again");

  }

  int j=add(2,3);

  System.out.println("The sum of c and d is: "+ j);

  finally {

   System.out.println("Code execution is finished");// throws and error, finally without try

  }

 }

}

/*

java: 'finally' without 'try'

 */
